{"content": {"suites": {"0": {"status": {"total_pass": 1, "total_skip": 0, "total_xpass": 0, "total_xfail": 0, "total_rerun": 0, "total_fail": 2, "total_error": 0}, "tests": {"0": {"status": "PASS", "message": "", "test_name": "test_getMainCategory", "rerun": "0"}, "1": {"status": "FAIL", "message": "           ConnectionRefusedError: [WinError 10061] No connection could be made because the target machine actively refused it\n       urllib3.exceptions.NewConnectionError: <urllib3.connection.HTTPConnection object at 0x00000192DF1B9410>: Failed to establish a new connection: [WinError 10061] No connection could be made because the target machine actively refused it\n       urllib3.exceptions.MaxRetryError: HTTPConnectionPool(host='localhost', port=8000): Max retries exceeded with url: /api/user/login (Caused by NewConnectionError('<urllib3.connection.HTTPConnection object at 0x00000192DF1B9410>: Failed to establish a new connection: [WinError 10061] No connection could be made because the target machine actively refused it'))\n       requests.exceptions.ConnectionError: HTTPConnectionPool(host='localhost', port=8000): Max retries exceeded with url: /api/user/login (Caused by NewConnectionError('<urllib3.connection.HTTPConnection object at 0x00000192DF1B9410>: Failed to establish a new connection: [WinError 10061] No connection could be made because the target machine actively refused it'))\n", "test_name": "test_createmaincategory", "rerun": "0"}, "2": {"status": "FAIL", "message": "           ConnectionRefusedError: [WinError 10061] No connection could be made because the target machine actively refused it\n       urllib3.exceptions.NewConnectionError: <urllib3.connection.HTTPConnection object at 0x00000192DF91EA50>: Failed to establish a new connection: [WinError 10061] No connection could be made because the target machine actively refused it\n       urllib3.exceptions.MaxRetryError: HTTPConnectionPool(host='localhost', port=8000): Max retries exceeded with url: /api/maincategory/6515da1d4ec99d181a0cd694 (Caused by NewConnectionError('<urllib3.connection.HTTPConnection object at 0x00000192DF91EA50>: Failed to establish a new connection: [WinError 10061] No connection could be made because the target machine actively refused it'))\n       requests.exceptions.ConnectionError: HTTPConnectionPool(host='localhost', port=8000): Max retries exceeded with url: /api/maincategory/6515da1d4ec99d181a0cd694 (Caused by NewConnectionError('<urllib3.connection.HTTPConnection object at 0x00000192DF91EA50>: Failed to establish a new connection: [WinError 10061] No connection could be made because the target machine actively refused it'))\n", "test_name": "test_updatemaincategory", "rerun": "0"}}, "suite_name": "TestCases/test_MainCategory.py"}}}, "date": "November 08, 2023", "start_time": 1699431756.3301558, "total_suite": 1, "status": "FAIL", "status_list": {"pass": "1", "fail": "2", "skip": "0", "error": "0", "xpass": "0", "xfail": "0", "rerun": "0"}, "total_tests": "3"}